<?xml version="1.0" encoding="utf-8"?>
<!-- This URDF was automatically created by SolidWorks to URDF Exporter! Originally created by Stephen Brawner (brawner@gmail.com) 
     Commit Version: 1.5.1-0-g916b5db  Build Version: 1.5.7152.31018
     For more information, please see http://wiki.ros.org/sw_urdf_exporter -->
<robot
  name="staubli" xmlns:xacro="http://www.ros.org/wiki/xacro">

  <xacro:macro name="box_inertial" params="m x y z rpy">
    <inertial>
      <origin xyz="0 ${y/2} 0" rpy="${rpy}" />
      <mass value="${m}"/>
      <inertia ixx="${1/12 * m * (y**2 + z**2)}" iyy="${1/12 * m * (x**2 + z**2)}" izz="${1/12 * m * (x**2 + y**2)}" ixy="0" ixz="0" iyz="0"/>
    </inertial>
  </xacro:macro>

  <!--  %%%%%%%%%%%%%%%%%%%%%%%%%%%%%%%%%%%%%%%%%%%%%%%%%%%%%%%%%%%%%%%%%%%%%%%%%%%%%%%%%%%%%%%%%%%%%%  -->
  <!--  For display  -->

  <link name="world" />
  <joint name="world_joint" type="fixed">
      <parent link="world" />
      <child link="table" />
      <origin xyz="0.0 0.0 0.0" rpy="0.0 0.0 0.0" />
  </joint>

   <link name="table" >
     <mass
        value="7.5748" />
      <inertia
        ixx="0.029538"
        ixy="-8.9594E-05"
        ixz="0.00038731"
        iyy="0.027722"
        iyz="9.1547E-06"
        izz="0.022274" />
      <visual>
        <geometry>
          <box size="1.0 1.2 0.01" />
        </geometry>
        <material name="LightGrey">
          <color rgba="0.7 0.7 0.7 1.0"/>
        </material>
      </visual>
      <collision>
        <origin xyz="0.0 0.0 0.005" rpy="0 0 0" />
        <geometry>
          <box size="1.0 1.2 0.01" />
        </geometry>
      </collision>
  </link>

  <joint name="base_to_table" type="fixed">
      <origin xyz="0 0 0.001" rpy="${-pi/2} 0.0 0.0"/>
      <parent link="table" />
      <child link = "base" />
  </joint>

  <link
    name="base">
    <inertial>
      <origin
        xyz="-0.036093 -0.0011918 0.08178"
        rpy="0 0 0" />
      <mass
        value="7.5748" />
      <inertia
        ixx="0.029538"
        ixy="-8.9594E-05"
        ixz="0.00038731"
        iyy="0.027722"
        iyz="9.1547E-06"
        izz="0.022274" />
    </inertial>
    <visual>
      <origin
        xyz="0 0 0"
        rpy="0 0 0" />
      <geometry>
        <mesh
          filename="package://staubli/meshes/base.STL" />
      </geometry>
      <material
        name="">
        <color
          rgba="0.79216 0.81961 0.93333 1" />
      </material>
    </visual>
    <collision>
      <origin
        xyz="0 0 0"
        rpy="0 0 0" />
      <geometry>
        <mesh
          filename="package://staubli/meshes/base.STL" />
      </geometry>
    </collision>
  </link>
  <link
    name="shoulder">
    <inertial>
      <origin
        xyz="-0.00023698 -0.13392 0.023184"
        rpy="0 0 0" />
      <mass
        value="7.2296" />
      <inertia
        ixx="0.059563"
        ixy="0.00017994"
        ixz="-4.0104E-05"
        iyy="0.037079"
        iyz="0.010038"
        izz="0.050678" />
    </inertial>
    <visual>
      <origin
        xyz="0 0 0"
        rpy="0 0 0" />
      <geometry>
        <mesh
          filename="package://staubli/meshes/shoulder.STL" />
      </geometry>
      <material
        name="">
        <color
          rgba="0.79216 0.81961 0.93333 1" />
      </material>
    </visual>
    <collision>
      <origin
        xyz="0 0 0"
        rpy="0 0 0" />
      <geometry>
        <mesh
          filename="package://staubli/meshes/shoulder.STL" />
      </geometry>
    </collision>
  </link>
  <joint
    name="base_shoulder_joint"
    type="revolute">
    <origin
      xyz="0 -0.19562 0"
      rpy="0 0 0" />
    <parent
      link="base" />
    <child
      link="shoulder" />
    <axis
      xyz="0 1 0" />
    <limit
      lower="-2.9671" upper="2.9671"
      effort="20"
      velocity="2" />
    <!--dynamics
      damping="0.7"
      friction="100" /-->
  </joint>
  <link
    name="arm">
    <inertial>
      <origin
        xyz="0.001767 -0.12741 0.041731"
        rpy="0 0 0" />
      <mass
        value="4.1314" />
      <inertia
        ixx="0.063289"
        ixy="0.00024419"
        ixz="2.1544E-05"
        iyy="0.0084984"
        iyz="-0.0015531"
        izz="0.068274" />
    </inertial>
    <visual>
      <origin
        xyz="0 0 0"
        rpy="0 0 0" />
      <geometry>
        <mesh
          filename="package://staubli/meshes/arm.STL" />
      </geometry>
      <material
        name="">
        <color
          rgba="0.79216 0.81961 0.93333 1" />
      </material>
    </visual>
    <collision>
      <origin
        xyz="0 0 0"
        rpy="0 0 0" />
      <geometry>
        <mesh
          filename="package://staubli/meshes/arm.STL" />
      </geometry>
    </collision>
  </link>
  <joint
    name="shoulder_arm_joint"
    type="revolute">
    <origin
      xyz="0 -0.18638 0.13"
      rpy="0 0 0.083621" />
    <parent
      link="shoulder" />
    <child
      link="arm" />
    <axis
      xyz="0 0 1" />
    <limit
      lower="-2.9671" upper="2.9671"
      effort="20"
      velocity="2" />
    <!--dynamics
      damping="0.7"
      friction="100" /-->
  </joint>
  <link
    name="elbow">
    <inertial>
      <origin
        xyz="-0.0038856 0.0079479 -0.10609"
        rpy="0 0 0" />
      <mass
        value="4.7834" />
      <inertia
        ixx="0.029621"
        ixy="0.00014964"
        ixz="-0.00068515"
        iyy="0.01953"
        iyz="-0.00061223"
        izz="0.022392" />
    </inertial>
    <visual>
      <origin
        xyz="0 0 0"
        rpy="0 0 0" />
      <geometry>
        <mesh
          filename="package://staubli/meshes/elbow.STL" />
      </geometry>
      <material
        name="">
        <color
          rgba="0.79216 0.81961 0.93333 1" />
      </material>
    </visual>
    <collision>
      <origin
        xyz="0 0 0"
        rpy="0 0 0" />
      <geometry>
        <mesh
          filename="package://staubli/meshes/elbow.STL" />
      </geometry>
    </collision>
  </link>
  <joint
    name="arm_elbow_joint"
    type="revolute">
    <origin
      xyz="0 -0.29 0"
      rpy="0 0 -0.083621" />
    <parent
      link="arm" />
    <child
      link="elbow" />
    <axis
      xyz="0 0 1" />
    <limit
      lower="-2.9671" upper="2.9671"
      effort="20"
      velocity="2" />
    <!--dynamics
      damping="0.7"
      friction="100" /-->
  </joint>
  <link
    name="forearm">
    <inertial>
      <origin
        xyz="-0.0028825 7.4416E-07 0.10602"
        rpy="0 0 0" />
      <mass
        value="2.2867" />
      <inertia
        ixx="0.0056823"
        ixy="3.2614E-08"
        ixz="-0.00022641"
        iyy="0.004438"
        iyz="-6.8535E-07"
        izz="0.0043222" />
    </inertial>
    <visual>
      <origin
        xyz="0 0 0"
        rpy="0 0 0" />
      <geometry>
        <mesh
          filename="package://staubli/meshes/forearm.STL" />
      </geometry>
      <material
        name="">
        <color
          rgba="0.79216 0.81961 0.93333 1" />
      </material>
    </visual>
    <collision>
      <origin
        xyz="0 0 0"
        rpy="0 0 0" />
      <geometry>
        <mesh
          filename="package://staubli/meshes/forearm.STL" />
      </geometry>
    </collision>
  </link>
  <joint
    name="elbow_forarm_joint"
    type="revolute">
    <origin
      xyz="0 -0.10845 -0.1253"
      rpy="1.5708 -0.9718 0" />
    <parent
      link="elbow" />
    <child
      link="forearm" />
    <axis
      xyz="0 0 1" />
    <limit
      lower="-2.9671" upper="2.9671"
      effort="20"
      velocity="2" />
    <!--dynamics
      damping="0.7"
      friction="100" /-->
  </joint>
  <link
    name="wrist">
    <inertial>
      <origin
        xyz="0.00019039 -0.01525 -0.00049904"
        rpy="0 0 0" />
      <mass
        value="0.11471" />
      <inertia
        ixx="8.4067E-05"
        ixy="-3.5655E-07"
        ixz="-4.7628E-11"
        iyy="2.9425E-05"
        iyz="4.1043E-09"
        izz="9.5321E-05" />
    </inertial>
    <visual>
      <origin
        xyz="0 0 0"
        rpy="0 0 0" />
      <geometry>
        <mesh
          filename="package://staubli/meshes/wrist.STL" />
      </geometry>
      <material
        name="">
        <color
          rgba="0.79216 0.81961 0.93333 1" />
      </material>
    </visual>
    <collision>
      <origin
        xyz="0 0 0"
        rpy="0 0 0" />
      <geometry>
        <mesh
          filename="package://staubli/meshes/wrist.STL" />
      </geometry>
    </collision>
  </link>
  <joint
    name="forarm_wrist_joint"
    type="revolute">
    <origin
      xyz="0 0 0.20175"
      rpy="-1.5708 0.23604 3.1416" />
    <parent
      link="forearm" />
    <child
      link="wrist" />
    <axis
      xyz="0 0 1" />
    <limit
      lower="-2.9671" upper="2.9671"
      effort="20"
      velocity="2" />
    <!--dynamics
      damping="0.7"
      friction="100" /-->
  </joint>
  <link
    name="flange">
    <inertial>
      <origin
        xyz="-0.00019716 2.5532E-09 0.010257"
        rpy="0 0 0" />
      <mass
        value="0.0088462" />
      <inertia
        ixx="1.0446E-06"
        ixy="1.8452E-11"
        ixz="6.6235E-09"
        iyy="1.0168E-06"
        iyz="1.3124E-15"
        izz="1.5808E-06" />
    </inertial>
    <visual>
      <origin
        xyz="0 0 0"
        rpy="0 0 0" />
      <geometry>
        <mesh
          filename="package://staubli/meshes/flange.STL" />
      </geometry>
      <material
        name="">
        <color
          rgba="0.79216 0.81961 0.93333 1" />
      </material>
    </visual>
    <collision>
      <origin
        xyz="0 0 0"
        rpy="0 0 0" />
      <geometry>
        <mesh
          filename="package://staubli/meshes/flange.STL" />
      </geometry>
    </collision>
  </link>
  <joint
    name="wrist_flange_joint"
    type="revolute">
    <origin
      xyz="0 -0.062155 -0.0005"
      rpy="-1.5708 -0.9718 3.1416" />
    <parent
      link="wrist" />
    <child
      link="flange" />
    <axis
      xyz="0 0 1" />
    <limit
      lower="-2.9671" upper="2.9671"
      effort="20"
      velocity="2" />
    <!--dynamics
      damping="0.7"
      friction="100" /-->
  </joint>
</robot>